2024-08-28 01:10:41,001 - app - ERROR - Exception on /register/ [POST]
Traceback (most recent call last):
  File "/home/malladipradyumna/Desktop/Vurbalize/PoetryBackend/venv/lib/python3.10/site-packages/sqlalchemy/engine/base.py", line 1967, in _exec_single_context
    self.dialect.do_execute(
  File "/home/malladipradyumna/Desktop/Vurbalize/PoetryBackend/venv/lib/python3.10/site-packages/sqlalchemy/engine/default.py", line 941, in do_execute
    cursor.execute(statement, parameters)
sqlite3.OperationalError: no such table: user

The above exception was the direct cause of the following exception:

Traceback (most recent call last):
  File "/home/malladipradyumna/Desktop/Vurbalize/PoetryBackend/venv/lib/python3.10/site-packages/flask/app.py", line 1473, in wsgi_app
    response = self.full_dispatch_request()
  File "/home/malladipradyumna/Desktop/Vurbalize/PoetryBackend/venv/lib/python3.10/site-packages/flask/app.py", line 882, in full_dispatch_request
    rv = self.handle_user_exception(e)
  File "/home/malladipradyumna/Desktop/Vurbalize/PoetryBackend/venv/lib/python3.10/site-packages/flask_cors/extension.py", line 178, in wrapped_function
    return cors_after_request(app.make_response(f(*args, **kwargs)))
  File "/home/malladipradyumna/Desktop/Vurbalize/PoetryBackend/venv/lib/python3.10/site-packages/flask/app.py", line 880, in full_dispatch_request
    rv = self.dispatch_request()
  File "/home/malladipradyumna/Desktop/Vurbalize/PoetryBackend/venv/lib/python3.10/site-packages/flask/app.py", line 865, in dispatch_request
    return self.ensure_sync(self.view_functions[rule.endpoint])(**view_args)  # type: ignore[no-any-return]
  File "/home/malladipradyumna/Desktop/Vurbalize/PoetryBackend/app/controllers/auth.py", line 25, in register
    if User.query.filter_by(email=data['email']).first():
  File "/home/malladipradyumna/Desktop/Vurbalize/PoetryBackend/venv/lib/python3.10/site-packages/sqlalchemy/orm/query.py", line 2728, in first
    return self.limit(1)._iter().first()  # type: ignore
  File "/home/malladipradyumna/Desktop/Vurbalize/PoetryBackend/venv/lib/python3.10/site-packages/sqlalchemy/orm/query.py", line 2827, in _iter
    result: Union[ScalarResult[_T], Result[_T]] = self.session.execute(
  File "/home/malladipradyumna/Desktop/Vurbalize/PoetryBackend/venv/lib/python3.10/site-packages/sqlalchemy/orm/session.py", line 2362, in execute
    return self._execute_internal(
  File "/home/malladipradyumna/Desktop/Vurbalize/PoetryBackend/venv/lib/python3.10/site-packages/sqlalchemy/orm/session.py", line 2247, in _execute_internal
    result: Result[Any] = compile_state_cls.orm_execute_statement(
  File "/home/malladipradyumna/Desktop/Vurbalize/PoetryBackend/venv/lib/python3.10/site-packages/sqlalchemy/orm/context.py", line 293, in orm_execute_statement
    result = conn.execute(
  File "/home/malladipradyumna/Desktop/Vurbalize/PoetryBackend/venv/lib/python3.10/site-packages/sqlalchemy/engine/base.py", line 1418, in execute
    return meth(
  File "/home/malladipradyumna/Desktop/Vurbalize/PoetryBackend/venv/lib/python3.10/site-packages/sqlalchemy/sql/elements.py", line 515, in _execute_on_connection
    return connection._execute_clauseelement(
  File "/home/malladipradyumna/Desktop/Vurbalize/PoetryBackend/venv/lib/python3.10/site-packages/sqlalchemy/engine/base.py", line 1640, in _execute_clauseelement
    ret = self._execute_context(
  File "/home/malladipradyumna/Desktop/Vurbalize/PoetryBackend/venv/lib/python3.10/site-packages/sqlalchemy/engine/base.py", line 1846, in _execute_context
    return self._exec_single_context(
  File "/home/malladipradyumna/Desktop/Vurbalize/PoetryBackend/venv/lib/python3.10/site-packages/sqlalchemy/engine/base.py", line 1986, in _exec_single_context
    self._handle_dbapi_exception(
  File "/home/malladipradyumna/Desktop/Vurbalize/PoetryBackend/venv/lib/python3.10/site-packages/sqlalchemy/engine/base.py", line 2355, in _handle_dbapi_exception
    raise sqlalchemy_exception.with_traceback(exc_info[2]) from e
  File "/home/malladipradyumna/Desktop/Vurbalize/PoetryBackend/venv/lib/python3.10/site-packages/sqlalchemy/engine/base.py", line 1967, in _exec_single_context
    self.dialect.do_execute(
  File "/home/malladipradyumna/Desktop/Vurbalize/PoetryBackend/venv/lib/python3.10/site-packages/sqlalchemy/engine/default.py", line 941, in do_execute
    cursor.execute(statement, parameters)
sqlalchemy.exc.OperationalError: (sqlite3.OperationalError) no such table: user
[SQL: SELECT user.id AS user_id, user.name AS user_name, user.email AS user_email, user.password_hash AS user_password_hash, user.credits_left AS user_credits_left 
FROM user 
WHERE user.email = ?
 LIMIT ? OFFSET ?]
[parameters: ('f20210367@hyderabad.bits-pilani.ac.in', 1, 0)]
(Background on this error at: https://sqlalche.me/e/20/e3q8)
2024-08-28 01:12:40,085 - app - INFO - PoetryBackend startup
2024-08-28 01:13:00,871 - app - INFO - PoetryBackend startup
2024-08-28 01:19:14,534 - app - INFO - PoetryBackend startup
2024-08-28 01:21:01,923 - app - INFO - PoetryBackend startup
2024-08-28 01:21:35,174 - app - INFO - PoetryBackend startup
